Workbook

Sheet Watchlist Ratings
A1: WATCHLIST RATINGS — JP Morgan Equity Research Framework | Long-Term Investor View
A2: MARKET DATA | J2: RATING 1 — STRUCTURAL QUALITY (Normalized 0–10) | T2: RATING 2 — ECONOMIC QUALITY & VALUE CREATION (Normalized 0–10) | AD2: RATING 3 — DURABILITY & EXISTENTIAL RISK (Normalized 0–10) | AN2: COMPOSITE RATING (0–10 avg) | AO2: Financials information | BJ2: Future valuation range | BN2: Actualizaciones y resultados
A3: Company Name Name | B3: Ticker Symbol | C3: Category | D3: Estilo inversión | E3: Exchange Listing | F3: Currency | G3: Price Local ccy | H3: Shares Outstanding millions | I3: Market Cap local ccy, m | J3: Mission (-1 to 2) | K3: MOAT (0 to 8) | L3: Optionality (0 to 3) | M3: Financials (-1 to 1) | N3: Concentration (-3 to 0) | O3: Glassdoor (-1 to 1) | P3: Founder/CEO (0 to 1) | Q3: Ownership (-1 to 1) | R3: R1 Sum (max 17) | S3: RATING 1 0–10 | T3: Financials (0 to 17) | U3: MOAT (0 to 20) | V3: Potential (0 to 18) | W3: Customers (0 to 10) | X3: Revenue Quality (0 to 10) | Y3: Mgmt & Culture (0 to 14) | Z3: Stock & Ownership (0 to 11) | AA3: Risks (-44 to 0) | AB3: R2 Sum (max 100) | AC3: RATING 2 0–10 | AD3: Durability (0 to 15) | AE3: Risk of Disappearance (-20 to 0) | AF3: Capital Intensity (0 to 10) | AG3: Capital Allocation (0 to 15) | AH3: Financing Source (-10 to 5) | AI3: Incentives (0 to 10) | AJ3: MOAT Structural (0 to 15) | AK3: Terminal Risk (-20 to 0) | AL3: R3 Sum (max 70) | AM3: RATING 3 0–10 | AO3: FX Reporting | AP3: Cash & Equivalents | AQ3: Total Debt | AR3: Enterprise Value | AS3: FCF LTM (unlevered) | AT3: NOPAT LTM | AU3: EBITDA LTM | AV3: Revenue LTM | AW3: EV / FCF | AX3: EV / EBITDA | AY3: EV / Sales | AZ3: Capital Employed | BA3: NOPAT M% | BB3: Asset Turnover | BC3: ROIC | BD3: FCF @5y Min | BE3: FCF min CAGR | BF3: FCF @5y Max | BG3: FCF max CAGR | BH3: Exit Mult Min | BI3: Exit Mult Max | BJ3: FVE min | BK3: FVE max | BL3: Worst IRR | BM3: Best IRR | BN3: Última actualización | BO3: Últimos resultados | BP3: Próximos resultados | BQ3: SBC LTM | BR3: Capex de crecimiento | BS3: FCF normalizado | BT3: Fuente del SBC
A4: #VALUE! | B4: {=_FV(A4,"Símbolo bursátil",TRUE())} -> VEEV | C4: Vertical Saas | D4: Compounder | E4: {=_FV(A4,"Abreviatura de intercambio",TRUE())} -> XNYS | F4: {=_FV(A4,"Moneda")} -> USD | G4: {=_FV(A4,"Precio")} -> 316.55 | H4: {=_FV(A4,"Acciones en circulación",TRUE)/1000000} -> 161.9088 | I4: =G4*H4 -> 51252.231 | J4: 1.5 | K4: 8 | L4: 2 | M4: 1 | N4: -1.5 | O4: 0.72 | P4: 1 | Q4: 1 | R4: =SUM(J4:N4)+SUM(P4:Q4) -> 13 | S4: =ROUND(R4/16*10,2) -> 8.13 | T4: 17 | U4: 18 | V4: 16 | W4: 8 | X4: 9 | Y4: 12 | Z4: 10 | AA4: -8 | AB4: =SUM(T4:AA4) -> 82 | AC4: =ROUND(AB4/10,2) -> 8.2 | AD4: 14 | AE4: 0 | AF4: 10 | AG4: 14 | AH4: 5 | AI4: 8 | AJ4: 14 | AK4: -5 | AL4: =SUM(AD4:AK4) -> 60 | AM4: =ROUND(AL4/70*10,2) -> 8.57 | AN4: =ROUND(S4*0.2+AC4*0.4+AM4*0.4,2) -> 8.33 | AO4: USD | AP4: 7242.9 | AQ4: 0 | AR4: =I4-AP4+AQ4 -> 44009.331 | AS4: 1144.2 | AT4: 791 | AV4: 3458.1 | AW4: =AR4/AS4 -> 38.46297 | AX4: =AR4/AU4 -> #VALUE! | AY4: =AR4/AV4 -> 12.726448 | AZ4: 1500 | BA4: =AT4/AV4 -> 0.22873832 | BB4: =AV4/AZ4 -> 2.3054 | BC4: =BA4*BB4 -> 0.52733333 | BD4: 1068.8 | BE4: =(BD4/AS4)^(1/5)-1 -> -0.013541316 | BF4: 2347.5 | BG4: =(BF4/AS4)^(1/5)-1 -> 0.15457123 | BH4: 18 | BI4: 30 | BJ4: =(BD4*BH4+$AP4-$AQ4)/$H4 -> 163.55689 | BK4: =(BF4*BI4+$AP4-$AQ4)/$H4 -> 479.70154 | BL4: =IF($BJ4<=0,-0.99,MAX(-0.99,($BJ4/G4)^(1/5)-1)) -> -0.12371514 | BM4: =IF(BK4<=0,-0.99,MAX(-0.99,(BK4/G4)^(1/5)-1)) -> 0.086690219 | BN4: 2026-09-27 | BO4: 26/08/2026 | BP4: 19/11/2026 | BQ4: 494.6 | BR4: 0 | BS4: 1144.2 | BT4: FUENTE: 10-Q Q2 FY27 (EDGAR XBRL, LTM = H1 FY27 + FY26 - H1 FY26). OCF 1.665,5 - capex (software capitalizado) 26,7 - SBC 494,6 = 1.144,2. Caja 1.812 + inversiones 5.430,9. Sin deuda financiera (arrend. operativos fuera, US GAAP). EBITDA pendiente (D&A no etiquetada completa). Proximos resultados ESTIMADOS por patron (Q3 FY26 fue el 20-nov-2025)
A5: #VALUE! | B5: {=_FV(A5,"Símbolo bursátil",TRUE())} -> MSFT | C5: Mag 7 | D5: Compounder | E5: {=_FV(A5,"Abreviatura de intercambio",TRUE())} -> XNAS | F5: {=_FV(A5,"Moneda")} -> USD | G5: {=_FV(A5,"Precio")} -> 534.27 | H5: {=_FV(A5,"Acciones en circulación",TRUE())/1000000} -> 7425.545 | I5: =G5*H5 -> 3967245.9 | J5: 1 | K5: 8 | L5: 3 | M5: 1 | N5: 0 | O5: 0.8 | P5: 1 | Q5: 0 | R5: =SUM(J5:N5)+SUM(P5:Q5) -> 14 | S5: =ROUND(R5/16*10,2) -> 8.75 | T5: 16 | U5: 19 | V5: 15 | W5: 10 | X5: 9 | Y5: 13 | Z5: 7 | AA5: -12 | AB5: =SUM(T5:AA5) -> 77 | AC5: =ROUND(AB5/10,2) -> 7.7 | AD5: 14 | AE5: 0 | AF5: 4 | AG5: 14 | AH5: 5 | AI5: 9 | AJ5: 13 | AK5: -6 | AL5: =SUM(AD5:AK5) -> 53 | AM5: =ROUND(AL5/70*10,2) -> 7.57 | AN5: =ROUND(S5*0.2+AC5*0.4+AM5*0.4,2) -> 7.86 | AO5: USD | AP5: 76843 | AQ5: 40294 | AR5: =I5-AP5+AQ5 -> 3930696.9 | AS5: 54582 | AT5: 125127 | AU5: 193771 | AV5: 331839 | AW5: =AR5/AS5 -> 72.014527 | AX5: =AR5/AU5 -> 20.285269 | AY5: =AR5/AV5 -> 11.845193 | AZ5: 589551 | BA5: =AT5/AV5 -> 0.37707141 | BB5: =AV5/AZ5 -> 0.56286733 | BC5: =BA5*BB5 -> 0.21224118 | BD5: 147461.2 | BE5: =(BD5/BS5)^(1/5)-1 -> 0.030193356 | BF5: 223734.1 | BG5: =(BF5/BS5)^(1/5)-1 -> 0.11977206 | BH5: 20 | BI5: 30 | BJ5: =(BD5*BH5+$AP5-$AQ5)/$H5 -> 402.0948 | BK5: =(BF5*BI5+$AP5-$AQ5)/$H5 -> 908.83188 | BL5: =IF($BJ5<=0,-0.99,MAX(-0.99,($BJ5/G5)^(1/5)-1)) -> -0.055257326 | BM5: =IF(BK5<=0,-0.99,MAX(-0.99,(BK5/G5)^(1/5)-1)) -> 0.11210182 | BN5: 46256 | BO5: 29/07/2026 | BP5: 28/10/2026 | BQ5: 12405 | BR5: 72500 | BS5: 127082 | BT5: FCF@5y NORMALIZADO el 4-oct-2026 por decision de Roger: BD/BF del 8-sep x BS/AS (127.082/54.582 = 2,328). BD 63.334,9 -> 147.461,2; BF 96.094,3 -> 223.734,1. CAGR sobre el normalizado 3,0% / 12,0% (las de Roger). BE/BG pasan a medirse contra BS. Multiplos sin cambio por decision de Roger: se calibraron el 22-ago sobre FCF@5y normalizado.
A6: #VALUE! | B6: {=_FV(A6,"Símbolo bursátil",TRUE())} -> ADYEN | C6: Fintech | D6: Compounder | E6: {=_FV(A6,"Abreviatura de intercambio",TRUE())} -> XAMS | F6: {=_FV(A6,"Moneda")} -> EUR | G6: {=_FV(A6,"Precio")} -> 930.4 | H6: {=_FV(A6,"Acciones en circulación",TRUE())/1000000} -> 31.69488 | I6: =G6*H6 -> 29488.916 | J6: 1 | K6: 7 | L6: 2 | M6: 1 | N6: -0.5 | O6: 0.74 | P6: 1 | Q6: 1 | R6: =SUM(J6:N6)+SUM(P6:Q6) -> 12.5 | S6: =ROUND(R6/16*10,2) -> 7.81 | T6: 15.5 | U6: 18 | V6: 13 | W6: 8 | X6: 7.5 | Y6: 11 | Z6: 10 | AA6: -10 | AB6: =SUM(T6:AA6) -> 73 | AC6: =ROUND(AB6/10,2) -> 7.3 | AD6: 13 | AE6: -1 | AF6: 9 | AG6: 14 | AH6: 5 | AI6: 10 | AJ6: 14 | AK6: -6 | AL6: =SUM(AD6:AK6) -> 58 | AM6: =ROUND(AL6/70*10,2) -> 8.29 | AN6: =ROUND(S6*0.2+AC6*0.4+AM6*0.4,2) -> 7.8 | AO6: EUR | AP6: 2710 | AQ6: 0 | AR6: =I6-AP6+AQ6 -> 26778.916 | AS6: 1098 | AT6: 895 | AU6: 1344 | AV6: 2573.6 | AW6: =AR6/AS6 -> 24.388813 | AX6: =AR6/AU6 -> 19.924789 | AY6: =AR6/AV6 -> 10.405236 | AZ6: 2500 | BA6: =AT6/AV6 -> 0.34776189 | BB6: =AV6/AZ6 -> 1.02944 | BC6: =BA6*BB6 -> 0.358 | BD6: 959.1 | BE6: =(BD6/AS6)^(1/5)-1 -> -0.026687479 | BF6: 2581.2 | BG6: =(BF6/AS6)^(1/5)-1 -> 0.18643476 | BH6: 17.5 | BI6: 28 | BJ6: =(BD6*BH6+$AP6-$AQ6)/$H6 -> 615.05991 | BK6: =(BF6*BI6+$AP6-$AQ6)/$H6 -> 2365.7954 | BL6: =IF($BJ6<=0,-0.99,MAX(-0.99,($BJ6/G6)^(1/5)-1)) -> -0.079445419 | BM6: =IF(BK6<=0,-0.99,MAX(-0.99,(BK6/G6)^(1/5)-1)) -> 0.20520658 | BN6: 2026-09-12 | BO6: 13/08/2026 | BP6: 28/10/2026 | BQ6: 43 | BR6: 0 | BS6: 1098 | BT6: LTM H1-26 (H2-25+H1-26). FCF honesto: EBITDA 1.344 - capex 128 - leases 25 - impuestos ~380 + intereses del float ~330 - SBC 43 = ~1.098 (def. Adyen 86% conv. = 1.156 sin impuestos). OJO: ~330 son intereses sobre fondos de comercios, bajan con tipos. Caja neta REAL 2.710 (3.000 - Orb 290), no la del balance. Antes AS=864 venia de OCF yfinance contaminado por fondos de comercios. FCF@5y sin escalar
A7: #VALUE! | B7: {=_FV(A7,"Símbolo bursátil",TRUE())} -> BN | C7: Real Assets | D7: Compounder | E7: {=_FV(A7,"Abreviatura de intercambio",TRUE())} -> XNYS | F7: {=_FV(A7,"Moneda")} -> USD | G7: {=_FV(A7,"Precio")} -> 36.395 | H7: {=_FV(A7,"Acciones en circulación",TRUE())/1000000} -> 2452.011 | I7: =G7*H7 -> 89240.94 | J7: 1 | K7: 7 | L7: 3 | M7: 0.5 | N7: 0 | O7: 0.66 | P7: 1 | Q7: 1 | R7: =SUM(J7:N7)+SUM(P7:Q7) -> 13.5 | S7: =ROUND(R7/16*10,2) -> 8.44 | T7: 13 | U7: 17 | V7: 15 | W7: 10 | X7: 9 | Y7: 14 | Z7: 10 | AA7: -8 | AB7: =SUM(T7:AA7) -> 80 | AC7: =ROUND(AB7/10,2) -> 8 | AD7: 14 | AE7: -1 | AF7: 5 | AG7: 15 | AH7: 2 | AI7: 10 | AJ7: 14 | AK7: -5 | AL7: =SUM(AD7:AK7) -> 54 | AM7: =ROUND(AL7/70*10,2) -> 7.71 | AN7: =ROUND(S7*0.2+AC7*0.4+AM7*0.4,2) -> 7.97 | AO7: USD | AP7: 10000 | AQ7: 17815 | AR7: =I7-AP7+AQ7 -> 97055.94 | AS7: 6080 | AT7: 5700 | AU7: 5700 | AV7: 80690 | AW7: =AR7/AS7 -> 15.963148 | AX7: =AR7/AU7 -> 17.027358 | AY7: =AR7/AV7 -> 1.2028249 | AZ7: 42483 | BA7: =AT7/AV7 -> 0.070640724 | BB7: =AV7/AZ7 -> 1.899348 | BC7: =BA7*BB7 -> 0.13417132 | BD7: 6712.5 | BE7: =(BD7/AS7)^(1/5)-1 -> 0.01999054 | BF7: 11199 | BG7: =(BF7/AS7)^(1/5)-1 -> 0.12993935 | BH7: 17.5 | BI7: 25 | BJ7: =(BD7*BH7+$AP7-$AQ7)/$H7 -> 44.719926 | BK7: =(BF7*BI7+$AP7-$AQ7)/$H7 -> 110.99461 | BL7: =IF($BJ7<=0,-0.99,MAX(-0.99,($BJ7/G7)^(1/5)-1)) -> 0.042057947 | BM7: =IF(BK7<=0,-0.99,MAX(-0.99,(BK7/G7)^(1/5)-1)) -> 0.24983313 | BN7: 2026-08-26 | BO7: 13/08/2026 | BP7: 12/11/2026 | BQ7: 120 | BR7: 0 | BS7: 6080 | BT7: DE non-GAAP LTM Q2-26 (6.200 = 2,61 $/acc) menos SBC equity-settled 120 (40-F FY25). NO usar OCF-capex consolidado | Investor Day 17-sep-2026 (segunda mano): el valor del plan, 140 $/accion, pasa de 2030 a 2031; DE antes de realizaciones 5.300 (2026) -> 11.600 (2031)
A8: #VALUE! | B8: {=_FV(A8,"Símbolo bursátil",TRUE())} -> COST | C8: Defensive | D8: Defensive | E8: {=_FV(A8,"Abreviatura de intercambio",TRUE())} -> XNAS | F8: {=_FV(A8,"Moneda")} -> USD | G8: {=_FV(A8,"Precio")} -> 994.68 | H8: {=_FV(A8,"Acciones en circulación",TRUE())/1000000} -> 443.1294 | I8: =G8*H8 -> 440771.95 | J8: 1.5 | K8: 8 | L8: 1 | M8: 1 | N8: 0 | O8: 0.78 | P8: 1 | Q8: 0 | R8: =SUM(J8:N8)+SUM(P8:Q8) -> 12.5 | S8: =ROUND(R8/16*10,2) -> 7.81 | T8: 15 | U8: 19 | V8: 13 | W8: 10 | X8: 10 | Y8: 13 | Z8: 7 | AA8: -7 | AB8: =SUM(T8:AA8) -> 80 | AC8: =ROUND(AB8/10,2) -> 8 | AD8: 15 | AE8: 0 | AF8: 6 | AG8: 13 | AH8: 5 | AI8: 9 | AJ8: 14 | AK8: -3 | AL8: =SUM(AD8:AK8) -> 59 | AM8: =ROUND(AL8/70*10,2) -> 8.43 | AN8: =ROUND(S8*0.2+AC8*0.4+AM8*0.4,2) -> 8.13 | AO8: USD | AP8: 21301 | AQ8: 6162 | AR8: =I8-AP8+AQ8 -> 425632.95 | AS8: 8479 | AT8: 8799 | AU8: 14250 | AV8: 303154 | AW8: =AR8/AS8 -> 50.198485 | AX8: =AR8/AU8 -> 29.868979 | AY8: =AR8/AV8 -> 1.4040156 | AZ8: 44305 | BA8: =AT8/AV8 -> 0.029024852 | BB8: =AV8/AZ8 -> 6.8424331 | BC8: =BA8*BB8 -> 0.19860061 | BD8: 10565.4 | BE8: =(BD8/AS8)^(1/5)-1 -> 0.044980681 | BF8: 13913.8 | BG8: =(BF8/AS8)^(1/5)-1 -> 0.10413004 | BH8: 20 | BI8: 30 | BJ8: =(BD8*BH8+$AP8-$AQ8)/$H8 -> 511.01777 | BK8: =(BF8*BI8+$AP8-$AQ8)/$H8 -> 976.13248 | BL8: =IF($BJ8<=0,-0.99,MAX(-0.99,($BJ8/G8)^(1/5)-1)) -> -0.12471291 | BM8: =IF(BK8<=0,-0.99,MAX(-0.99,(BK8/G8)^(1/5)-1)) -> -0.0037574755 | BN8: 2026-09-27 | BO8: 24/09/2026 | BP8: 10/12/2026 | BQ8: 911 | BR8: 3870 | BS8: 12349 | BT8: FUENTE: 8-K Q4 FY26 (24-sep-2026): ingresos 303.154, EBIT 11.685, OCF 15.825, capex 6.435, caja 20.207 + inv. 1.094, deuda 2.248 + 3.914. SBC 911 y D&A 2.565 son LTM a Q3 (10-Q) hasta el 10-K de octubre. FCF-SBC 8.479; capex de crecimiento 6.435 - 2.565 = 3.870 -> normalizado 12.349. FCF@5y DEVUELTO a los valores de Roger (el 26-sep los escale sin preguntar). Proximos: estimado 10-dic
A9: #VALUE! | B9: {=_FV(A9,"Símbolo bursátil",TRUE())} -> DSGX | C9: Vertical Saas | D9: Compounder | E9: {=_FV(A9,"Abreviatura de intercambio",TRUE())} -> XNAS | F9: {=_FV(A9,"Moneda")} -> USD | G9: {=_FV(A9,"Precio")} -> 87.415 | H9: {=_FV(A9,"Acciones en circulación",TRUE())/1000000} -> 85.54855 | I9: =G9*H9 -> 7478.2265 | J9: 1 | K9: 7 | L9: 2 | M9: 1 | N9: 0 | O9: 0.8 | P9: 0.5 | Q9: 0 | R9: =SUM(J9:N9)+SUM(P9:Q9) -> 11.5 | S9: =ROUND(R9/16*10,2) -> 7.19 | T9: 16 | U9: 17 | V9: 11 | W9: 10 | X9: 9 | Y9: 13 | Z9: 6 | AA9: -7 | AB9: =SUM(T9:AA9) -> 75 | AC9: =ROUND(AB9/10,2) -> 7.5 | AD9: 14 | AE9: 0 | AF9: 10 | AG9: 13 | AH9: 5 | AI9: 8 | AJ9: 14 | AK9: -3 | AL9: =SUM(AD9:AK9) -> 61 | AM9: =ROUND(AL9/70*10,2) -> 8.71 | AN9: =ROUND(S9*0.2+AC9*0.4+AM9*0.4,2) -> 7.92 | AO9: USD | AP9: 182 | AQ9: 8.1 | AR9: =I9-AP9+AQ9 -> 7304.3265 | AS9: 271.4 | AT9: 178 | AU9: 357 | AV9: 775.1 | AW9: =AR9/AS9 -> 26.91351 | AX9: =AR9/AU9 -> 20.460298 | AY9: =AR9/AV9 -> 9.4237215 | AZ9: 1676 | BA9: =AT9/AV9 -> 0.22964779 | BB9: =AV9/AZ9 -> 0.46247017 | BC9: =BA9*BB9 -> 0.10620525 | BD9: 282.8 | BE9: =(BD9/AS9)^(1/5)-1 -> 0.0082631906 | BF9: 570 | BG9: =(BF9/AS9)^(1/5)-1 -> 0.15998668 | BH9: 17.5 | BI9: 27 | BJ9: =(BD9*BH9+$AP9-$AQ9)/$H9 -> 59.882955 | BK9: =(BF9*BI9+$AP9-$AQ9)/$H9 -> 181.93061 | BL9: =IF($BJ9<=0,-0.99,MAX(-0.99,($BJ9/G9)^(1/5)-1)) -> -0.072863983 | BM9: =IF(BK9<=0,-0.99,MAX(-0.99,(BK9/G9)^(1/5)-1)) -> 0.1578811 | BN9: 2026-09-11 | BO9: 10/09/2026 | BP9: 02/12/2026 | BQ9: 27.1 | BR9: 0 | BS9: 271.4 | BT9: trimestral (Q2 FY27: 8,0 incl. impuestos asociados). Caja PRO FORMA 182 = 401,1 - Tai 99,3 - Extensiv 119,9 (cerradas tras el balance). Proximos resultados: estimacion
A10: #VALUE! | B10: {=_FV(A10,"Símbolo bursátil",TRUE())} -> RAA | C10: Hardware | D10: Compounder | E10: {=_FV(A10,"Abreviatura de intercambio",TRUE())} -> XFRA | F10: {=_FV(A10,"Moneda")} -> EUR | G10: {=_FV(A10,"Precio")} -> 612.5 | H10: {=_FV(A10,"Acciones en circulación",TRUE())/1000000} -> 11.37 | I10: =G10*H10 -> 6964.125 | J10: 1 | K10: 7 | L10: 2 | M10: 1 | N10: -1 | O10: 0.82 | P10: 1 | Q10: 1 | R10: =SUM(J10:N10)+SUM(P10:Q10) -> 12 | S10: =ROUND(R10/16*10,2) -> 7.5 | T10: 15 | U10: 17 | V10: 10 | W10: 9 | X10: 8 | Y10: 13 | Z10: 10 | AA10: -8 | AB10: =SUM(T10:AA10) -> 74 | AC10: =ROUND(AB10/10,2) -> 7.4 | AD10: 14 | AE10: -1 | AF10: 8 | AG10: 13 | AH10: 5 | AI10: 9 | AJ10: 13 | AK10: -3 | AL10: =SUM(AD10:AK10) -> 58 | AM10: =ROUND(AL10/70*10,2) -> 8.29 | AN10: =ROUND(S10*0.2+AC10*0.4+AM10*0.4,2) -> 7.78 | AO10: EUR | AP10: 280 | AQ10: 20 | AR10: =I10-AP10+AQ10 -> 6704.125 | AS10: 235.5 | AT10: 230 | AU10: 350 | AV10: 1296 | AW10: =AR10/AS10 -> 28.467622 | AX10: =AR10/AU10 -> 19.154643 | AY10: =AR10/AV10 -> 5.172936 | AZ10: 600 | BA10: =AT10/AV10 -> 0.17746914 | BB10: =AV10/AZ10 -> 2.16 | BC10: =BA10*BB10 -> 0.38333333 | BD10: 300.7 | BE10: =(BD10/AS10)^(1/5)-1 -> 0.050094789 | BF10: 433.9 | BG10: =(BF10/AS10)^(1/5)-1 -> 0.13000339 | BH10: 15 | BI10: 27 | BJ10: =(BD10*BH10+$AP10-$AQ10)/$H10 -> 419.56904 | BK10: =(BF10*BI10+$AP10-$AQ10)/$H10 -> 1053.2366 | BL10: =IF($BJ10<=0,-0.99,MAX(-0.99,($BJ10/G10)^(1/5)-1)) -> -0.072872488 | BM10: =IF(BK10<=0,-0.99,MAX(-0.99,(BK10/G10)^(1/5)-1)) -> 0.11451 | BN10: 2026-08-25 | BO10: 06/08/2026 | BP10: 05/11/2026 | BQ10: 0 | BR10: 3.2 | BS10: 238.7 | BT10: no reportado (0)
A11: #VALUE! | B11: {=_FV(A11,"Símbolo bursátil",TRUE())} -> ZS | C11: Cyber | D11: Growth | E11: {=_FV(A11,"Abreviatura de intercambio",TRUE())} -> XNAS | F11: {=_FV(A11,"Moneda")} -> USD | G11: {=_FV(A11,"Precio")} -> 213.11 | H11: {=_FV(A11,"Acciones en circulación",TRUE())/1000000} -> 163.0547 | I11: =G11*H11 -> 34748.587 | J11: 1 | K11: 6 | L11: 2 | M11: 1 | N11: 0 | O11: 0.72 | P11: 1 | Q11: 1 | R11: =SUM(J11:N11)+SUM(P11:Q11) -> 12 | S11: =ROUND(R11/16*10,2) -> 7.5 | T11: 13 | U11: 15 | V11: 14 | W11: 8 | X11: 9 | Y11: 12 | Z11: 10 | AA11: -11 | AB11: =SUM(T11:AA11) -> 70 | AC11: =ROUND(AB11/10,2) -> 7 | AD11: 13 | AE11: -2 | AF11: 9 | AG11: 11 | AH11: 4 | AI11: 9 | AJ11: 12 | AK11: -5 | AL11: =SUM(AD11:AK11) -> 51 | AM11: =ROUND(AL11/70*10,2) -> 7.29 | AN11: =ROUND(S11*0.2+AC11*0.4+AM11*0.4,2) -> 7.22 | AO11: USD | AP11: 3474.2 | AQ11: 1696.4 | AR11: =I11-AP11+AQ11 -> 32970.787 | AS11: -42.7 | AT11: -133.3 | AU11: 15.2 | AV11: 3352.5 | AW11: =AR11/AS11 -> -772.14958 | AX11: =AR11/AU11 -> 2169.1307 | AY11: =AR11/AV11 -> 9.8346867 | AZ11: 4597 | BA11: =AT11/AV11 -> -0.039761372 | BB11: =AV11/AZ11 -> 0.72927997 | BC11: =BA11*BB11 -> -0.028997172 | BD11: 125 | BE11: =(BD11/AS11)^(1/5)-1 -> -2.2396424 | BF11: 314.5 | BG11: =(BF11/AS11)^(1/5)-1 -> -2.4908658 | BH11: 20 | BI11: 30 | BJ11: =(BD11*BH11+$AP11-$AQ11)/$H11 -> 26.235368 | BK11: =(BF11*BI11+$AP11-$AQ11)/$H11 -> 68.767107 | BL11: =IF($BJ11<=0,-0.99,MAX(-0.99,($BJ11/G11)^(1/5)-1)) -> -0.34225635 | BM11: =IF(BK11<=0,-0.99,MAX(-0.99,(BK11/G11)^(1/5)-1)) -> -0.20245465 | BN11: 2026-09-27 | BO11: 03/09/2026 | BP11: 24/11/2026 | BQ11: 821.9 | BR11: 202 | BS11: 159.3 | BT11: FUENTE: 10-K FY26 (EDGAR XBRL). OCF 1.129,7 - capex 277,3 - software 73,2 - SBC 821,9 = -42,7. D&A 148,5 -> capex de crecimiento 202,0 -> normalizado 159,3. Caja 928,4 + inversiones 2.545,8. Convertibles 1.696,4. Proximos ESTIMADOS por patron
A12: #VALUE! | B12: {=_FV(A12,"Símbolo bursátil",TRUE())} -> NTO | C12: IP owner | D12: Compounder | E12: {=_FV(A12,"Abreviatura de intercambio",TRUE())} -> XFRA | F12: {=_FV(A12,"Moneda")} -> EUR | G12: {=_FV(A12,"Precio")} -> 47.98 | H12: {=_FV(A12,"Acciones en circulación",TRUE())/1000000} -> 1287.26 | I12: =G12*H12 -> 61762.735 | J12: 1 | K12: 7 | L12: 3 | M12: 1 | N12: -1 | O12: 0.82 | P12: 1 | Q12: 0 | R12: =SUM(J12:N12)+SUM(P12:Q12) -> 12 | S12: =ROUND(R12/16*10,2) -> 7.5 | T12: 16 | U12: 17 | V12: 14 | W12: 10 | X12: 8 | Y12: 12 | Z12: 6 | AA12: -8 | AB12: =SUM(T12:AA12) -> 75 | AC12: =ROUND(AB12/10,2) -> 7.5 | AD12: 14 | AE12: -1 | AF12: 9 | AG12: 12 | AH12: 5 | AI12: 7 | AJ12: 14 | AK12: -3 | AL12: =SUM(AD12:AK12) -> 57 | AM12: =ROUND(AL12/70*10,2) -> 8.14 | AN12: =ROUND(S12*0.2+AC12*0.4+AM12*0.4,2) -> 7.76 | AO12: JPY | AP12: 1967908 | AQ12: 0 | AR12: =I12*'Framework Notes'!E4-AP12+AQ12 -> 9008565.2 | AS12: 262620 | AT12: 325400 | AU12: 461600 | AV12: 2258501 | AW12: =AR12/AS12 -> 34.302663 | AX12: =AR12/AU12 -> 19.515956 | AY12: =AR12/AV12 -> 3.9887364 | AZ12: 1600000 | BA12: =AT12/AV12 -> 0.14407786 | BB12: =AV12/AZ12 -> 1.4115631 | BC12: =BA12*BB12 -> 0.203375 | BD12: 262620 | BE12: =(BD12/AS12)^(1/5)-1 -> 0 | BF12: 483861 | BG12: =(BF12/AS12)^(1/5)-1 -> 0.13000031 | BH12: 15 | BI12: 22.5 | BJ12: =((BD12*BH12+$AP12-$AQ12)/$H12)/'Framework Notes'!E4 -> 25.821394 | BK12: =((BF12*BI12+$AP12-$AQ12)/$H12)/'Framework Notes'!E4 -> 56.190395 | BL12: =IF($BJ12<=0,-0.99,MAX(-0.99,($BJ12/G12)^(1/5)-1)) -> -0.11654611 | BM12: =IF(BK12<=0,-0.99,MAX(-0.99,(BK12/G12)^(1/5)-1)) -> 0.03209665 | BN12: 2026-08-25 | BO12: 06/08/2026 | BP12: 05/11/2026 | BQ12: 0 | BR12: 11315 | BS12: 273935 | BT12: no reportado (0)
A13: #VALUE! | B13: {=_FV(A13,"Símbolo bursátil",TRUE())} -> AMZN | C13: Mag 7 | D13: Compounder | E13: {=_FV(A13,"Abreviatura de intercambio",TRUE())} -> XNAS | F13: {=_FV(A13,"Moneda")} -> USD | G13: {=_FV(A13,"Precio")} -> 262.278 | H13: {=_FV(A13,"Acciones en circulación",TRUE())/1000000} -> 10786.31 | I13: =G13*H13 -> 2829011.8 | J13: 1.5 | K13: 8 | L13: 3 | M13: 1 | N13: 0 | O13: 0.72 | P13: 1 | Q13: 0.5 | R13: =SUM(J13:N13)+SUM(P13:Q13) -> 15 | S13: =ROUND(R13/16*10,2) -> 9.38 | T13: 14 | U13: 19 | V13: 15 | W13: 10 | X13: 9 | Y13: 12 | Z13: 6 | AA13: -8 | AB13: =SUM(T13:AA13) -> 77 | AC13: =ROUND(AB13/10,2) -> 7.7 | AD13: 14 | AE13: -1 | AF13: 3 | AG13: 13 | AH13: 4 | AI13: 8 | AJ13: 14 | AK13: -5 | AL13: =SUM(AD13:AK13) -> 50 | AM13: =ROUND(AL13/70*10,2) -> 7.14 | AN13: =ROUND(S13*0.2+AC13*0.4+AM13*0.4,2) -> 7.81 | AO13: USD | AP13: 78213 | AQ13: 128894 | AR13: =I13-AP13+AQ13 -> 2879692.8 | AS13: 58282 | AT13: 55000 | AU13: 138000 | AV13: 775656 | AW13: =AR13/AS13 -> 49.409643 | AX13: =AR13/AU13 -> 20.867339 | AY13: =AR13/AV13 -> 3.7125901 | AZ13: 300000 | BA13: =AT13/AV13 -> 0.070907722 | BB13: =AV13/AZ13 -> 2.58552 | BC13: =BA13*BB13 -> 0.18333333 | BD13: 70864 | BE13: =(BD13/AS13)^(1/5)-1 -> 0.039868071 | BF13: 122401.4 | BG13: =(BF13/AS13)^(1/5)-1 -> 0.1599797 | BH13: 22.5 | BI13: 30 | BJ13: =(BD13*BH13+$AP13-$AQ13)/$H13 -> 143.12207 | BK13: =(BF13*BI13+$AP13-$AQ13)/$H13 -> 335.73678 | BL13: =IF($BJ13<=0,-0.99,MAX(-0.99,($BJ13/G13)^(1/5)-1)) -> -0.11409134 | BM13: =IF(BK13<=0,-0.99,MAX(-0.99,(BK13/G13)^(1/5)-1)) -> 0.050624228 | BN13: 2026-08-25 | BO13: 30/07/2026 | BP13: 29/10/2026 | BQ13: 19810 | BR13: 80564 | BS13: 58282 | BT13: NORMALIZADO: FCF-SBC -22.282 + capex crecimiento 80.564 (capex 151.003 - D&A 70.439 como mantenimiento). TTM Q2-26. FCF@5y escalado x0,758
A14: #VALUE! | B14: {=_FV(A14,"Símbolo bursátil",TRUE())} -> SU | C14: Electrify | D14: Compounder | E14: {=_FV(A14,"Abreviatura de intercambio",TRUE())} -> XPAR | F14: {=_FV(A14,"Moneda")} -> EUR | G14: {=_FV(A14,"Precio")} -> 252.6 | H14: {=_FV(A14,"Acciones en circulación",TRUE())/1000000} -> 578.6053 | I14: =G14*H14 -> 146155.7 | J14: 1 | K14: 7 | L14: 3 | M14: 1 | N14: 0 | O14: 0.84 | P14: 1 | Q14: 0 | R14: =SUM(J14:N14)+SUM(P14:Q14) -> 13 | S14: =ROUND(R14/16*10,2) -> 8.13 | T14: 15 | U14: 17 | V14: 15 | W14: 10 | X14: 9 | Y14: 13 | Z14: 5 | AA14: -7 | AB14: =SUM(T14:AA14) -> 77 | AC14: =ROUND(AB14/10,2) -> 7.7 | AD14: 14 | AE14: -1 | AF14: 6 | AG14: 13 | AH14: 3 | AI14: 8 | AJ14: 13 | AK14: -3 | AL14: =SUM(AD14:AK14) -> 53 | AM14: =ROUND(AL14/70*10,2) -> 7.57 | AN14: =ROUND(S14*0.2+AC14*0.4+AM14*0.4,2) -> 7.73 | AO14: EUR | AP14: 4520 | AQ14: 20810 | AR14: =I14-AP14+AQ14 -> 162445.7 | AS14: 4588 | AT14: 5727 | AU14: 8520 | AV14: 42040 | AW14: =AR14/AS14 -> 35.406648 | AX14: =AR14/AU14 -> 19.066397 | AY14: =AR14/AV14 -> 3.8640747 | AZ14: 43259 | BA14: =AT14/AV14 -> 0.1362274 | BB14: =AV14/AZ14 -> 0.97182089 | BC14: =BA14*BB14 -> 0.13238864 | BD14: 5855.3 | BE14: =(BD14/AS14)^(1/5)-1 -> 0.049989965 | BF14: 8453.1 | BG14: =(BF14/AS14)^(1/5)-1 -> 0.1300002 | BH14: 17.5 | BI14: 25 | BJ14: =(BD14*BH14+$AP14-$AQ14)/$H14 -> 148.94048 | BK14: =(BF14*BI14+$AP14-$AQ14)/$H14 -> 337.08212 | BL14: =IF($BJ14<=0,-0.99,MAX(-0.99,($BJ14/G14)^(1/5)-1)) -> -0.10026238 | BM14: =IF(BK14<=0,-0.99,MAX(-0.99,(BK14/G14)^(1/5)-1)) -> 0.059401232 | BN14: 2026-08-26 | BO14: 30/07/2026 | BP14: 29/10/2026 | BQ14: 0 | BR14: 0 | BS14: 4588 | BT14: no reportado (0)
A15: #VALUE! | B15: {=_FV(A15,"Símbolo bursátil",TRUE())} -> ITX | C15: Consumo | D15: Compounder | E15: {=_FV(A15,"Abreviatura de intercambio",TRUE())} -> BMEX | F15: {=_FV(A15,"Moneda")} -> EUR | G15: {=_FV(A15,"Precio")} -> 55.42 | H15: {=_FV(A15,"Acciones en circulación",TRUE())/1000000} -> 3116.652 | I15: =G15*H15 -> 172724.85 | J15: 0 | K15: 6.5 | L15: 1.5 | M15: 1 | N15: 0 | O15: 0.74 | P15: 1 | Q15: 1 | R15: =SUM(J15:N15)+SUM(P15:Q15) -> 11 | S15: =ROUND(R15/16*10,2) -> 6.88 | T15: 16 | U15: 17 | V15: 10 | W15: 10 | X15: 9 | Y15: 13 | Z15: 10 | AA15: -8 | AB15: =SUM(T15:AA15) -> 77 | AC15: =ROUND(AB15/10,2) -> 7.7 | AD15: 15 | AE15: -1 | AF15: 8 | AG15: 13 | AH15: 5 | AI15: 9 | AJ15: 13 | AK15: -4 | AL15: =SUM(AD15:AK15) -> 58 | AM15: =ROUND(AL15/70*10,2) -> 8.29 | AN15: =ROUND(S15*0.2+AC15*0.4+AM15*0.4,2) -> 7.77 | AO15: EUR | AP15: 10399 | AQ15: 1 | AR15: =I15-AP15+AQ15 -> 162326.85 | AS15: 5706 | AT15: 6241 | AU15: 9797 | AV15: 41262 | AW15: =AR15/AS15 -> 28.44845 | AX15: =AR15/AU15 -> 16.569037 | AY15: =AR15/AV15 -> 3.934052 | AZ15: 24023 | BA15: =AT15/AV15 -> 0.15125297 | BB15: =AV15/AZ15 -> 1.717604 | BC15: =BA15*BB15 -> 0.2597927 | BD15: 7080.8 | BE15: =(BD15/AS15)^(1/5)-1 -> 0.044119272 | BF15: 8954.9 | BG15: =(BF15/AS15)^(1/5)-1 -> 0.094323674 | BH15: 16 | BI15: 24 | BJ15: =(BD15*BH15+$AP15-$AQ15)/$H15 -> 39.687074 | BK15: =(BF15*BI15+$AP15-$AQ15)/$H15 -> 72.294116 | BL15: =IF($BJ15<=0,-0.99,MAX(-0.99,($BJ15/G15)^(1/5)-1)) -> -0.064601836 | BM15: =IF(BK15<=0,-0.99,MAX(-0.99,(BK15/G15)^(1/5)-1)) -> 0.054598831 | BN15: 2026-09-27 | BO15: 09/09/2026 | BP15: 02/12/2026 | BQ15: 113 | BR15: 0 | BS15: 5706 | BT15: FUENTE: cuentas anuales consolidadas FY25 (nota 8, nota 16, estado de cambios en el patrimonio), nota FY25 y anexos H1-26 de Inditex. LTM = FY25 + H1-26 - H1-25. FCF de Inditex DESPUES DE ALQUILERES: OCF 10.439 - capex 2.750 - pagos fijos de arrendamiento 1.870 = 5.819; menos SBC 113 (reconocimiento de pagos en acciones FY25, proxy LTM) = 5.706. Deuda solo financiera (1); pasivos por arrendamiento 6.197 fuera. EBITDA post-alquileres 11.666 - 1.870. Capex de crecimiento (capex - amortizacion de inmovilizado SIN derechos de uso): FY25 2.712 - 1.545 = 1.167; NO sumado en BS hasta que Roger decida (deep dive 27-sep, pregunta 1). FCF@5y y multiplos provisionales (pregunta 2). 9M: 2-dic-2026 (Inditex)
A16: #VALUE! | B16: {=_FV(A16,"Símbolo bursátil",TRUE())} -> LOTB | C16: Consumo | D16: Compounder | E16: {=_FV(A16,"Abreviatura de intercambio",TRUE())} -> XBRU | F16: {=_FV(A16,"Moneda")} -> EUR | G16: {=_FV(A16,"Precio")} -> 13000 | H16: {=_FV(A16,"Acciones en circulación",TRUE())/1000000} -> 0.81601 | I16: =G16*H16 -> 10608.13 | J16: 0 | K16: 7 | L16: 3 | M16: 1 | N16: -1 | O16: 0.76 | P16: 1 | Q16: 1 | R16: =SUM(J16:N16)+SUM(P16:Q16) -> 12 | S16: =ROUND(R16/16*10,2) -> 7.5 | T16: 16 | U16: 16 | V16: 14 | W16: 9 | X16: 9 | Y16: 13 | Z16: 10 | AA16: -7 | AB16: =SUM(T16:AA16) -> 80 | AC16: =ROUND(AB16/10,2) -> 8 | AD16: 14 | AE16: -1 | AF16: 6 | AG16: 13 | AH16: 4 | AI16: 9 | AJ16: 13 | AK16: -3 | AL16: =SUM(AD16:AK16) -> 55 | AM16: =ROUND(AL16/70*10,2) -> 7.86 | AN16: =ROUND(S16*0.2+AC16*0.4+AM16*0.4,2) -> 7.84 | AO16: EUR | AP16: 274 | AQ16: 409 | AR16: =I16-AP16+AQ16 -> 10743.13 | AS16: 90.8 | AT16: 190 | AU16: 291 | AV16: 1450 | AW16: =AR16/AS16 -> 118.31641 | AX16: =AR16/AU16 -> 36.917973 | AY16: =AR16/AV16 -> 7.4090552 | AZ16: 1309 | BA16: =AT16/AV16 -> 0.13103448 | BB16: =AV16/AZ16 -> 1.1077158 | BC16: =BA16*BB16 -> 0.14514897 | BD16: 127.5 | BE16: =(BD16/AS16)^(1/5)-1 -> 0.07024909 | BF16: 167.5 | BG16: =(BF16/AS16)^(1/5)-1 -> 0.13027935 | BH16: 15 | BI16: 25 | BJ16: =(BD16*BH16+$AP16-$AQ16)/$H16 -> 2178.2821 | BK16: =(BF16*BI16+$AP16-$AQ16)/$H16 -> 4966.2382 | BL16: =IF($BJ16<=0,-0.99,MAX(-0.99,($BJ16/G16)^(1/5)-1)) -> -0.3004252 | BM16: =IF(BK16<=0,-0.99,MAX(-0.99,(BK16/G16)^(1/5)-1)) -> -0.17507049 | BN16: 2026-08-25 | BO16: 07/08/2026 | BP16: 25/02/2027 | BQ16: 2.1 | BR16: 72.8 | BS16: 163.6 | BT16: anual
A17: #VALUE! | B17: {=_FV(A17,"Símbolo bursátil",TRUE())} -> HLMA | C17: Healthcare | D17: Compounder | E17: {=_FV(A17,"Abreviatura de intercambio",TRUE())} -> XLON | F17: {=_FV(A17,"Moneda")} -> GBp | G17: {=_FV(A17,"Precio")} -> 3412 | H17: {=_FV(A17,"Acciones en circulación",TRUE())/1000000} -> 379.6453 | I17: =G17/100*H17 -> 12953.498 | J17: 2 | K17: 6 | L17: 3 | M17: 1 | N17: 0 | O17: 0.86 | P17: 1 | Q17: 0 | R17: =SUM(J17:N17)+SUM(P17:Q17) -> 13 | S17: =ROUND(R17/16*10,2) -> 8.13 | T17: 13 | U17: 15 | V17: 12 | W17: 10 | X17: 10 | Y17: 12 | Z17: 6 | AA17: -7 | AB17: =SUM(T17:AA17) -> 71 | AC17: =ROUND(AB17/10,2) -> 7.1 | AD17: 15 | AE17: -1 | AF17: 8 | AG17: 14 | AH17: 4 | AI17: 8 | AJ17: 13 | AK17: -3 | AL17: =SUM(AD17:AK17) -> 58 | AM17: =ROUND(AL17/70*10,2) -> 8.29 | AN17: =ROUND(S17*0.2+AC17*0.4+AM17*0.4,2) -> 7.78 | AO17: GBP | AP17: 143.4 | AQ17: 913.4 | AR17: =I17-AP17+AQ17 -> 13723.498 | AS17: 392.4 | AT17: 403 | AU17: 622.8 | AV17: 2580 | AW17: =AR17/AS17 -> 34.973236 | AX17: =AR17/AU17 -> 22.03516 | AY17: =AR17/AV17 -> 5.3191851 | AZ17: 3191 | BA17: =AT17/AV17 -> 0.15620155 | BB17: =AV17/AZ17 -> 0.80852397 | BC17: =BA17*BB17 -> 0.1262927 | BD17: 500.8 | BE17: =(BD17/AS17)^(1/5)-1 -> 0.049994597 | BF17: 722.9 | BG17: =(BF17/AS17)^(1/5)-1 -> 0.12997763 | BH17: 18 | BI17: 28 | BJ17: =(BD17*BH17+$AP17-$AQ17)/$H17*100 -> 2171.606 | BK17: =(BF17*BI17+$AP17-$AQ17)/$H17*100 -> 5128.7873 | BL17: =IF($BJ17<=0,-0.99,MAX(-0.99,($BJ17/G17)^(1/5)-1)) -> -0.086403555 | BM17: =IF(BK17<=0,-0.99,MAX(-0.99,(BK17/G17)^(1/5)-1)) -> 0.084928539 | BN17: 2026-08-26 | BO17: 11/06/2026 | BP17: 19/11/2026 | BQ17: 17.2 | BR17: 0 | BS17: 392.4 | BT17: anual | Trading update 24-sep-2026 (RNS): guia de margen EBIT ajustado FY27 sube a 23,5-24% (antes ~22,7%); organico a divisa constante de dos digitos bajos (fotonica ~+30%, aporta ~5 pp); 6 adquisiciones por 515 M GBP (record) y 3 desinversiones por 83; la libra fuerte resta. Semestrales el 19-nov-2026 (confirmado)
A18: #VALUE! | B18: {=_FV(A18,"Símbolo bursátil",TRUE())} -> FICO | C18: Vertical Saas | D18: Compounder | E18: {=_FV(A18,"Abreviatura de intercambio",TRUE())} -> XNYS | F18: {=_FV(A18,"Moneda")} -> USD | G18: {=_FV(A18,"Precio")} -> 778.995 | H18: {=_FV(A18,"Acciones en circulación",TRUE())/1000000} -> 21.59764 | I18: =G18*H18 -> 16824.454 | J18: 0 | K18: 8 | L18: 2 | M18: 1 | N18: -1 | O18: 0.78 | P18: 1 | Q18: 0 | R18: =SUM(J18:N18)+SUM(P18:Q18) -> 11 | S18: =ROUND(R18/16*10,2) -> 6.88 | T18: 16 | U18: 19 | V18: 10 | W18: 7 | X18: 10 | Y18: 12 | Z18: 5 | AA18: -15 | AB18: =SUM(T18:AA18) -> 64 | AC18: =ROUND(AB18/10,2) -> 6.4 | AD18: 14 | AE18: 0 | AF18: 10 | AG18: 14 | AH18: 4 | AI18: 8 | AJ18: 13 | AK18: -7 | AL18: =SUM(AD18:AK18) -> 56 | AM18: =ROUND(AL18/70*10,2) -> 8 | AN18: =ROUND(S18*0.2+AC18*0.4+AM18*0.4,2) -> 7.14 | AO18: USD | AP18: 248.4 | AQ18: 5582.4 | AR18: =I18-AP18+AQ18 -> 22158.454 | AS18: 786.6 | AT18: 946 | AU18: 1252 | AV18: 2393.6 | AW18: =AR18/AS18 -> 28.169913 | AX18: =AR18/AU18 -> 17.698445 | AY18: =AR18/AV18 -> 9.2573753 | AZ18: 2200 | BA18: =AT18/AV18 -> 0.39522059 | BB18: =AV18/AZ18 -> 1.088 | BC18: =BA18*BB18 -> 0.43 | BD18: 730 | BE18: =(BD18/AS18)^(1/5)-1 -> -0.01482409 | BF18: 1670 | BG18: =(BF18/AS18)^(1/5)-1 -> 0.16249878 | BH18: 18 | BI18: 26 | BJ18: =(BD18*BH18+$AP18-$AQ18)/$H18 -> 361.42838 | BK18: =(BF18*BI18+$AP18-$AQ18)/$H18 -> 1763.4334 | BL18: =IF($BJ18<=0,-0.99,MAX(-0.99,($BJ18/G18)^(1/5)-1)) -> -0.14237484 | BM18: =IF(BK18<=0,-0.99,MAX(-0.99,(BK18/G18)^(1/5)-1)) -> 0.17751075 | BN18: 2026-08-26 | BO18: 29/07/2026 | BP18: 05/11/2026 | BQ18: 174.3 | BR18: 0 | BS18: 786.6 | BT18: FUENTE: 10-Q Q3 FY26 (EDGAR XBRL, 30-jun-2026). LTM: OCF 1.001,5 - capex 5,5 - software capitalizado 35,1 - SBC 174,3 = 786,6. Ingresos 2.393,6; EBIT 1.236,3; EBITDA 1.252 (EBIT + D&A 16,1); NOPAT 946 (EBIT x (1-23,5%)). Caja 248,4; deuda 5.582,4 (recompras de 3.046 en 9M financiadas con deuda; la fila llevaba 2.400, dato viejo). 28-sep-2026: la FHFA anuncia una sola tabla de precios (LLPA) para FICO Classic y VantageScore 4.0, sin el ajuste de 20 puntos: el riesgo regulatorio de la tesis se ha materializado. FCF@5y y multiplos pendientes de Roger. Proximos: ~5-nov-2026 (estimado)
A19: #VALUE! | B19: {=_FV(A19,"Símbolo bursátil",TRUE())} -> LIFCO B | C19: Industrial | D19: Compounder | E19: {=_FV(A19,"Abreviatura de intercambio",TRUE())} -> XSTO | F19: {=_FV(A19,"Moneda")} -> SEK | G19: {=_FV(A19,"Precio")} -> 327.6 | H19: {=_FV(A19,"Acciones en circulación",TRUE())/1000000} -> 423.8365 | I19: =G19*H19 -> 138848.84 | J19: 0 | K19: 7 | L19: 3 | M19: 1 | N19: 0 | O19: 0.7 | P19: 0.5 | Q19: 1 | R19: =SUM(J19:N19)+SUM(P19:Q19) -> 12.5 | S19: =ROUND(R19/16*10,2) -> 7.81 | T19: 15 | U19: 15 | V19: 12 | W19: 10 | X19: 9 | Y19: 13 | Z19: 10 | AA19: -7 | AB19: =SUM(T19:AA19) -> 77 | AC19: =ROUND(AB19/10,2) -> 7.7 | AD19: 14 | AE19: -1 | AF19: 7 | AG19: 14 | AH19: 4 | AI19: 9 | AJ19: 13 | AK19: -3 | AL19: =SUM(AD19:AK19) -> 57 | AM19: =ROUND(AL19/70*10,2) -> 8.14 | AN19: =ROUND(S19*0.2+AC19*0.4+AM19*0.4,2) -> 7.9 | AO19: SEK | AP19: 3000 | AQ19: 12500 | AR19: =I19-AP19+AQ19 -> 148348.84 | AS19: 4373 | AT19: 3400 | AU19: 6627 | AV19: 29251 | AW19: =AR19/AS19 -> 33.923814 | AX19: =AR19/AU19 -> 22.385519 | AY19: =AR19/AV19 -> 5.0715817 | AZ19: 22000 | BA19: =AT19/AV19 -> 0.11623534 | BB19: =AV19/AZ19 -> 1.3295909 | BC19: =BA19*BB19 -> 0.15454545 | BD19: 5069.2 | BE19: =(BD19/AS19)^(1/5)-1 -> 0.029987585 | BF19: 8331 | BG19: =(BF19/AS19)^(1/5)-1 -> 0.13758415 | BH19: 16 | BI19: 26 | BJ19: =(BD19*BH19+$AP19-$AQ19)/$H19 -> 168.95006 | BK19: =(BF19*BI19+$AP19-$AQ19)/$H19 -> 488.64598 | BL19: =IF($BJ19<=0,-0.99,MAX(-0.99,($BJ19/G19)^(1/5)-1)) -> -0.1240428 | BM19: =IF(BK19<=0,-0.99,MAX(-0.99,(BK19/G19)^(1/5)-1)) -> 0.083253464 | BN19: 2026-08-26 | BO19: 14/07/2026 | BP19: 22/10/2026 | BQ19: 0 | BR19: 0 | BS19: 4373 | BT19: no reportado (0)
A20: #VALUE! | B20: {=_FV(A20,"Símbolo bursátil",TRUE())} -> EVD | C20: Consumo | D20: Compounder | E20: {=_FV(A20,"Abreviatura de intercambio",TRUE())} -> XFRA | F20: {=_FV(A20,"Moneda")} -> EUR | G20: {=_FV(A20,"Precio")} -> 61 | H20: {=_FV(A20,"Acciones en circulación",TRUE())/1000000} -> 96 | I20: =G20*H20 -> 5856 | J20: 0.5 | K20: 7 | L20: 2 | M20: 0.5 | N20: -0.5 | O20: 0.5 | P20: 0.5 | Q20: 0.5 | R20: =SUM(J20:N20)+SUM(P20:Q20) -> 10.5 | S20: =ROUND(R20/16*10,2) -> 6.56 | T20: 14 | U20: 15.5 | V20: 14 | W20: 8 | X20: 7 | Y20: 12 | Z20: 9 | AA20: -12 | AB20: =SUM(T20:AA20) -> 67.5 | AC20: =ROUND(AB20/10,2) -> 6.75 | AD20: 13 | AE20: -5 | AF20: 8.5 | AG20: 12 | AH20: 3 | AI20: 8 | AJ20: 12.5 | AK20: -5 | AL20: =SUM(AD20:AK20) -> 47 | AM20: =ROUND(AL20/70*10,2) -> 6.71 | AN20: =ROUND(S20*0.2+AC20*0.4+AM20*0.4,2) -> 6.7 | AO20: EUR | AP20: 1605 | AQ20: 1404.2 | AR20: =I20-AP20+AQ20 -> 5655.2 | AS20: 60 | AT20: 331.4 | AU20: 603.1 | AV20: 3297.9 | AW20: =AR20/AS20 -> 94.253333 | AX20: =AR20/AU20 -> 9.3768861 | AY20: =AR20/AV20 -> 1.7147882 | AZ20: 1573 | BA20: =AT20/AV20 -> 0.10048819 | BB20: =AV20/AZ20 -> 2.0965671 | BC20: =BA20*BB20 -> 0.21068023 | BD20: 242.3 | BE20: =(BD20/AS20)^(1/5)-1 -> 0.32202733 | BF20: 445.1 | BG20: =(BF20/AS20)^(1/5)-1 -> 0.49300502 | BH20: 12 | BI20: 20 | BJ20: =(BD20*BH20+$AP20-$AQ20)/$H20 -> 32.379167 | BK20: =(BF20*BI20+$AP20-$AQ20)/$H20 -> 94.820833 | BL20: =IF($BJ20<=0,-0.99,MAX(-0.99,($BJ20/G20)^(1/5)-1)) -> -0.11897716 | BM20: =IF(BK20<=0,-0.99,MAX(-0.99,(BK20/G20)^(1/5)-1)) -> 0.092231724 | BN20: 2026-09-27 | BO20: 20/08/2026 | BP20: 12/11/2026 | BQ20: 0 | BR20: 203.4 | BS20: 263.4 | BT20: FUENTE: informe anual 2025 y semestral 2026 (corporate.eventim.de). OJO: 1.089 de la caja (dic-25) es DINERO DE ENTRADAS DE PROMOTORES; la propia CTS calcula caja neta 200,8 (caja+valores 1.605 - deuda incl. dinero de entradas y arrendamientos 1.404). FCF FY25 tras alquileres: OCF 364,7 - capex 278,9 - arrend. 25,8 = 60,0 (LTM no computable: el semestral no separa capex). Capex de crecimiento (Arena Milano) 278,9 - 75,5 = 203,4. El OCF lleva +49 de dinero de entradas: PREGUNTA ABIERTA de metodo. Proximos estimados | 30-sep-2026: el CFO William Willms sale del consejo con efecto inmediato, sin motivo comunicado; interino Philipp Knigge
A21: #VALUE! | B21: {=_FV(A21,"Símbolo bursátil",TRUE())} -> MNST | C21: Consumo | D21: Compounder | E21: {=_FV(A21,"Abreviatura de intercambio",TRUE())} -> XNAS | F21: {=_FV(A21,"Moneda")} -> USD | G21: {=_FV(A21,"Precio")} -> 47.1 | H21: {=_FV(A21,"Acciones en circulación",TRUE())/1000000} -> 1956.016 | I21: =G21*H21 -> 92128.354 | J21: 0 | K21: 7 | L21: 2 | M21: 1 | N21: -1 | O21: 0.78 | P21: 1 | Q21: 1 | R21: =SUM(J21:N21)+SUM(P21:Q21) -> 11 | S21: =ROUND(R21/16*10,2) -> 6.88 | T21: 16 | U21: 17 | V21: 12 | W21: 9 | X21: 9 | Y21: 12 | Z21: 9 | AA21: -9 | AB21: =SUM(T21:AA21) -> 75 | AC21: =ROUND(AB21/10,2) -> 7.5 | AD21: 13 | AE21: -1 | AF21: 9 | AG21: 12 | AH21: 5 | AI21: 9 | AJ21: 13 | AK21: -4 | AL21: =SUM(AD21:AK21) -> 56 | AM21: =ROUND(AL21/70*10,2) -> 8 | AN21: =ROUND(S21*0.2+AC21*0.4+AM21*0.4,2) -> 7.58 | AO21: USD | AP21: 3419 | AQ21: 93 | AR21: =I21-AP21+AQ21 -> 88802.354 | AS21: 1945.7 | AT21: 2154 | AU21: 2930 | AV21: 9220 | AW21: =AR21/AS21 -> 45.640311 | AX21: =AR21/AU21 -> 30.307971 | AY21: =AR21/AV21 -> 9.6314917 | AZ21: 9665 | BA21: =AT21/AV21 -> 0.23362256 | BB21: =AV21/AZ21 -> 0.95395758 | BC21: =BA21*BB21 -> 0.22286601 | BD21: 2367.3 | BE21: =(BD21/AS21)^(1/5)-1 -> 0.040005136 | BF21: 3745.9 | BG21: =(BF21/AS21)^(1/5)-1 -> 0.13997692 | BH21: 18 | BI21: 24 | BJ21: =(BD21*BH21+$AP21-$AQ21)/$H21 -> 23.485186 | BK21: =(BF21*BI21+$AP21-$AQ21)/$H21 -> 47.661982 | BL21: =IF($BJ21<=0,-0.99,MAX(-0.99,($BJ21/G21)^(1/5)-1)) -> -0.12992915 | BM21: =IF(BK21<=0,-0.99,MAX(-0.99,(BK21/G21)^(1/5)-1)) -> 0.0023750284 | BN21: 2026-08-25 | BO21: 06/08/2026 | BP21: 05/11/2026 | BQ21: 135.8 | BR21: 37.1 | BS21: 1982.8 | BT21: trimestral | 25-sep-2026 (8-K): Rob Gehring, CEO Americas, se va a Coca-Cola el 30-nov
A22: #VALUE! | B22: {=_FV(A22,"Símbolo bursátil",TRUE())} -> ABNB | C22: Consumo | D22: Growth | E22: {=_FV(A22,"Abreviatura de intercambio",TRUE())} -> XNAS | F22: {=_FV(A22,"Moneda")} -> USD | G22: {=_FV(A22,"Precio")} -> 175.025 | H22: {=_FV(A22,"Acciones en circulación",TRUE())/1000000} -> 589.5857 | I22: =G22*H22 -> 103192.24 | J22: 1.5 | K22: 6 | L22: 2 | M22: 1 | N22: 0 | O22: 0.82 | P22: 1 | Q22: 1 | R22: =SUM(J22:N22)+SUM(P22:Q22) -> 12.5 | S22: =ROUND(R22/16*10,2) -> 7.81 | T22: 14 | U22: 17 | V22: 14 | W22: 9 | X22: 7 | Y22: 12 | Z22: 9 | AA22: -10 | AB22: =SUM(T22:AA22) -> 72 | AC22: =ROUND(AB22/10,2) -> 7.2 | AD22: 12 | AE22: -2 | AF22: 10 | AG22: 11 | AH22: 4 | AI22: 8 | AJ22: 12 | AK22: -5 | AL22: =SUM(AD22:AK22) -> 50 | AM22: =ROUND(AL22/70*10,2) -> 7.14 | AN22: =ROUND(S22*0.2+AC22*0.4+AM22*0.4,2) -> 7.3 | AO22: USD | AP22: 12069 | AQ22: 2496 | AR22: =I22-AP22+AQ22 -> 93619.237 | AS22: 3153 | AT22: 2081 | AU22: 2874 | AV22: 13159 | AW22: =AR22/AS22 -> 29.692115 | AX22: =AR22/AU22 -> 32.574543 | AY22: =AR22/AV22 -> 7.1144644 | AZ22: 10662 | BA22: =AT22/AV22 -> 0.15814272 | BB22: =AV22/AZ22 -> 1.2341962 | BC22: =BA22*BB22 -> 0.19517914 | BD22: 3350.1 | BE22: =(BD22/AS22)^(1/5)-1 -> 0.012200995 | BF22: 6342.1 | BG22: =(BF22/AS22)^(1/5)-1 -> 0.15001055 | BH22: 16 | BI22: 24 | BJ22: =(BD22*BH22+$AP22-$AQ22)/$H22 -> 107.15083 | BK22: =(BF22*BI22+$AP22-$AQ22)/$H22 -> 274.40184 | BL22: =IF($BJ22<=0,-0.99,MAX(-0.99,($BJ22/G22)^(1/5)-1)) -> -0.093476442 | BM22: =IF(BK22<=0,-0.99,MAX(-0.99,(BK22/G22)^(1/5)-1)) -> 0.094100927 | BN22: 2026-08-25 | BO22: 06/08/2026 | BP22: 05/11/2026 | BQ22: 1707 | BR22: 0 | BS22: 3153 | BT22: trimestral
A23: #VALUE! | B23: {=_FV(A23,"Símbolo bursátil",TRUE())} -> DNP | C23: Defensive | D23: Defensive | E23: {=_FV(A23,"Abreviatura de intercambio",TRUE())} -> XWAR | F23: {=_FV(A23,"Moneda")} -> PLN | G23: {=_FV(A23,"Precio")} -> 38.7 | H23: {=_FV(A23,"Acciones en circulación",TRUE())/1000000} -> 980.4 | I23: =G23*H23 -> 37941.48 | J23: 0.5 | K23: 7 | L23: 2 | M23: 1 | N23: 0 | O23: 0.3 | P23: 1 | Q23: 1 | R23: =SUM(J23:N23)+SUM(P23:Q23) -> 12.5 | S23: =ROUND(R23/16*10,2) -> 7.81 | T23: 14 | U23: 16 | V23: 14 | W23: 10 | X23: 9 | Y23: 12 | Z23: 10 | AA23: -7 | AB23: =SUM(T23:AA23) -> 78 | AC23: =ROUND(AB23/10,2) -> 7.8 | AD23: 13 | AE23: -2 | AF23: 4 | AG23: 13 | AH23: 3 | AI23: 9 | AJ23: 13 | AK23: -4 | AL23: =SUM(AD23:AK23) -> 49 | AM23: =ROUND(AL23/70*10,2) -> 7 | AN23: =ROUND(S23*0.2+AC23*0.4+AM23*0.4,2) -> 7.48 | AO23: PLN | AP23: 771 | AQ23: 852 | AR23: =I23-AP23+AQ23 -> 38022.48 | AS23: 669.1 | AT23: 1656 | AU23: 2609 | AV23: 35628 | AW23: =AR23/AS23 -> 56.826304 | AX23: =AR23/AU23 -> 14.573584 | AY23: =AR23/AV23 -> 1.0672078 | AZ23: 9909 | BA23: =AT23/AV23 -> 0.046480296 | BB23: =AV23/AZ23 -> 3.5955192 | BC23: =BA23*BB23 -> 0.1671208 | BD23: 756.3 | BE23: =(BD23/AS23)^(1/5)-1 -> 0.024803533 | BF23: 1345.8 | BG23: =(BF23/AS23)^(1/5)-1 -> 0.15000015 | BH23: 15 | BI23: 20 | BJ23: =(BD23*BH23+$AP23-$AQ23)/$H23 -> 11.488678 | BK23: =(BF23*BI23+$AP23-$AQ23)/$H23 -> 27.371481 | BL23: =IF($BJ23<=0,-0.99,MAX(-0.99,($BJ23/G23)^(1/5)-1)) -> -0.21564654 | BM23: =IF(BK23<=0,-0.99,MAX(-0.99,(BK23/G23)^(1/5)-1)) -> -0.066923039 | BN23: 2026-08-25 | BO23: 13/08/2026 | BP23: 12/11/2026 | BQ23: 0 | BR23: 1460.2 | BS23: 2129.3 | BT23: no reportado (0)
A24: #VALUE! | B24: {=_FV(A24,"Símbolo bursátil",TRUE())} -> VLTO | C24: Industrial | D24: Compounder | E24: {=_FV(A24,"Abreviatura de intercambio",TRUE())} -> XNYS | F24: {=_FV(A24,"Moneda")} -> USD | G24: {=_FV(A24,"Precio")} -> 100.55 | H24: {=_FV(A24,"Acciones en circulación",TRUE())/1000000} -> 243.7933 | I24: =G24*H24 -> 24513.416 | J24: 2 | K24: 6.5 | L24: 1 | M24: 1 | N24: 0 | O24: 0 | P24: 0 | Q24: 0 | R24: =SUM(J24:N24)+SUM(P24:Q24) -> 10.5 | S24: =ROUND(R24/16*10,2) -> 6.56 | T24: 14 | U24: 17 | V24: 11 | W24: 10 | X24: 10 | Y24: 12 | Z24: 5 | AA24: -7 | AB24: =SUM(T24:AA24) -> 72 | AC24: =ROUND(AB24/10,2) -> 7.2 | AD24: 14 | AE24: -1 | AF24: 7 | AG24: 13 | AH24: 4 | AI24: 8 | AJ24: 13 | AK24: -3 | AL24: =SUM(AD24:AK24) -> 55 | AM24: =ROUND(AL24/70*10,2) -> 7.86 | AN24: =ROUND(S24*0.2+AC24*0.4+AM24*0.4,2) -> 7.34 | AO24: USD | AP24: 2120 | AQ24: 3590 | AR24: =I24-AP24+AQ24 -> 25983.416 | AS24: 973 | AT24: 1062 | AU24: 1390 | AV24: 5700 | AW24: =AR24/AS24 -> 26.704436 | AX24: =AR24/AU24 -> 18.693105 | AY24: =AR24/AV24 -> 4.5584941 | AZ24: 6501 | BA24: =AT24/AV24 -> 0.18631579 | BB24: =AV24/AZ24 -> 0.87678819 | BC24: =BA24*BB24 -> 0.16335948 | BD24: 1183.5 | BE24: =(BD24/AS24)^(1/5)-1 -> 0.039946708 | BF24: 1715.2 | BG24: =(BF24/AS24)^(1/5)-1 -> 0.12005767 | BH24: 12.5 | BI24: 20 | BJ24: =(BD24*BH24+$AP24-$AQ24)/$H24 -> 54.65183 | BK24: =(BF24*BI24+$AP24-$AQ24)/$H24 -> 134.67967 | BL24: =IF($BJ24<=0,-0.99,MAX(-0.99,($BJ24/G24)^(1/5)-1)) -> -0.11479364 | BM24: =IF(BK24<=0,-0.99,MAX(-0.99,(BK24/G24)^(1/5)-1)) -> 0.060190701 | BN24: 2026-08-26 | BO24: 28/07/2026 | BP24: 27/10/2026 | BQ24: 74 | BR24: 0 | BS24: 973 | BT24: trimestral
A25: #VALUE! | B25: {=_FV(A25,"Símbolo bursátil",TRUE())} -> LR | C25: Electrify | D25: Compounder | E25: {=_FV(A25,"Abreviatura de intercambio",TRUE())} -> XPAR | F25: {=_FV(A25,"Moneda")} -> EUR | G25: {=_FV(A25,"Precio")} -> 131.3 | H25: {=_FV(A25,"Acciones en circulación",TRUE())/1000000} -> 262.2457 | I25: =G25*H25 -> 34432.86 | J25: 1 | K25: 6 | L25: 2 | M25: 1 | N25: 0 | O25: 1 | P25: 0 | Q25: 0 | R25: =SUM(J25:N25)+SUM(P25:Q25) -> 10 | S25: =ROUND(R25/16*10,2) -> 6.25 | T25: 14 | U25: 14 | V25: 15 | W25: 10 | X25: 9 | Y25: 11 | Z25: 5 | AA25: -8 | AB25: =SUM(T25:AA25) -> 70 | AC25: =ROUND(AB25/10,2) -> 7 | AD25: 13 | AE25: -1 | AF25: 6 | AG25: 13 | AH25: 4 | AI25: 8 | AJ25: 12 | AK25: -3 | AL25: =SUM(AD25:AK25) -> 52 | AM25: =ROUND(AL25/70*10,2) -> 7.43 | AN25: =ROUND(S25*0.2+AC25*0.4+AM25*0.4,2) -> 7.02 | AO25: EUR | AP25: 1971 | AQ25: 7724 | AR25: =I25-AP25+AQ25 -> 40185.86 | AS25: 1256.4 | AT25: 1409 | AU25: 2319 | AV25: 10107 | AW25: =AR25/AS25 -> 31.984926 | AX25: =AR25/AU25 -> 17.328961 | AY25: =AR25/AV25 -> 3.9760424 | AZ25: 15683 | BA25: =AT25/AV25 -> 0.13940833 | BB25: =AV25/AZ25 -> 0.64445578 | BC25: =BA25*BB25 -> 0.089842505 | BD25: 1682.1 | BE25: =(BD25/AS25)^(1/5)-1 -> 0.060094977 | BF25: 2527.8 | BG25: =(BF25/AS25)^(1/5)-1 -> 0.15006651 | BH25: 13 | BI25: 24 | BJ25: =(BD25*BH25+$AP25-$AQ25)/$H25 -> 61.447337 | BK25: =(BF25*BI25+$AP25-$AQ25)/$H25 -> 209.39981 | BL25: =IF($BJ25<=0,-0.99,MAX(-0.99,($BJ25/G25)^(1/5)-1)) -> -0.14089219 | BM25: =IF(BK25<=0,-0.99,MAX(-0.99,(BK25/G25)^(1/5)-1)) -> 0.097848245 | BN25: 2026-08-26 | BO25: 06/08/2026 | BP25: 05/11/2026 | BQ25: 0 | BR25: 0 | BS25: 1256.4 | BT25: SBC no reportado (0). Capital Markets Day 28/29-sep-2026: objetivos 2027-30 suben a organico +6-8%/anio (antes +3-5%) + ~5% de perimetro, margen operativo ajustado 21-22%, FCF 13-15% de ventas, ~60% del FCF a adquisiciones, payout ~50%, deuda neta/EBITDA 1,5-2,5x, desinversiones de 0,5-1,0 mil M EUR de ventas; centros de datos 32% de ventas (>3.000 M EUR en 2026). Cifras LTM pendientes de fuente primaria (revisar NIIF 16)
A26: #VALUE! | B26: {=_FV(A26,"Símbolo bursátil",TRUE())} -> JDG | C26: Healthcare | D26: Compounder | E26: {=_FV(A26,"Abreviatura de intercambio",TRUE())} -> XLON | F26: {=_FV(A26,"Moneda")} -> GBp | G26: {=_FV(A26,"Precio")} -> 3430 | H26: {=_FV(A26,"Acciones en circulación",TRUE())/1000000} -> 6.66069 | I26: =G26/100*H26 -> 228.46167 | J26: 1 | K26: 5 | L26: 2 | M26: 0 | N26: 0 | O26: 1 | P26: 1 | Q26: 1 | R26: =SUM(J26:N26)+SUM(P26:Q26) -> 10 | S26: =ROUND(R26/16*10,2) -> 6.25 | T26: 12 | U26: 13 | V26: 12 | W26: 10 | X26: 8 | Y26: 13 | Z26: 10 | AA26: -9 | AB26: =SUM(T26:AA26) -> 69 | AC26: =ROUND(AB26/10,2) -> 6.9 | AD26: 13 | AE26: -2 | AF26: 6 | AG26: 13 | AH26: 2 | AI26: 9 | AJ26: 11 | AK26: -4 | AL26: =SUM(AD26:AK26) -> 48 | AM26: =ROUND(AL26/70*10,2) -> 6.86 | AN26: =ROUND(S26*0.2+AC26*0.4+AM26*0.4,2) -> 6.75 | AO26: GBP | AP26: 15.6 | AQ26: 60.9 | AR26: =I26-AP26+AQ26 -> 273.76167 | AS26: 11.8 | AT26: 3 | AU26: 21.6 | AV26: 131.3 | AW26: =AR26/AS26 -> 23.200141 | AX26: =AR26/AU26 -> 12.674151 | AY26: =AR26/AV26 -> 2.0850089 | AZ26: 158 | BA26: =AT26/AV26 -> 0.022848439 | BB26: =AV26/AZ26 -> 0.83101266 | BC26: =BA26*BB26 -> 0.018987342 | BD26: 22.5 | BE26: =(BD26/AS26)^(1/5)-1 -> 0.13778473 | BF26: 48.3 | BG26: =(BF26/AS26)^(1/5)-1 -> 0.32560162 | BH26: 10 | BI26: 20 | BJ26: =(BD26*BH26+$AP26-$AQ26)/$H26*100 -> 2697.9187 | BK26: =(BF26*BI26+$AP26-$AQ26)/$H26*100 -> 13822.892 | BL26: =IF($BJ26<=0,-0.99,MAX(-0.99,($BJ26/G26)^(1/5)-1)) -> -0.046881395 | BM26: =IF(BK26<=0,-0.99,MAX(-0.99,(BK26/G26)^(1/5)-1)) -> 0.32148111 | BN26: 2026-09-27 | BO26: 23/09/2026 | BP26: 21/01/2027 | BQ26: 1.2 | BR26: 0 | BS26: 11.8 | BT26: FUENTE: RNS interinos 23-sep-2026 + preliminares FY25. FCF sin intereses, tras alquileres y SBC: FY25 ~19,8 - 1S25 6,1 + 1S26 (-1,9) = 11,8 LTM (arrend. FY25 ~1,8 estimado). Deuda 58,6 + contraprestaciones 2,3 (excl. NIIF 16); caja 15,6 -> 45,3 = deuda neta ajustada de la compania, 2,1x su EBITDA de covenant (21,6). NOPAT estatutario LTM ~3. FCF@5y SIN escalar. Proximo: trading update (estimado)
A27: #VALUE! | B27: {=_FV(A27,"Símbolo bursátil",TRUE())} -> STMN | C27: Healthcare | D27: Compounder | E27: {=_FV(A27,"Abreviatura de intercambio",TRUE())} -> XSWX | F27: {=_FV(A27,"Moneda")} -> CHF | G27: {=_FV(A27,"Precio")} -> 92.96 | H27: {=_FV(A27,"Acciones en circulación",TRUE())/1000000} -> 159.4552 | I27: =G27*H27 -> 14822.955 | J27: 2 | K27: 6 | L27: 2 | M27: 0 | N27: 0 | O27: 1 | P27: 0 | Q27: 0 | R27: =SUM(J27:N27)+SUM(P27:Q27) -> 10 | S27: =ROUND(R27/16*10,2) -> 6.25 | T27: 12 | U27: 15 | V27: 12 | W27: 9 | X27: 9 | Y27: 11 | Z27: 5 | AA27: -8 | AB27: =SUM(T27:AA27) -> 65 | AC27: =ROUND(AB27/10,2) -> 6.5 | AD27: 13 | AE27: -1 | AF27: 7 | AG27: 12 | AH27: 3 | AI27: 7 | AJ27: 12 | AK27: -3 | AL27: =SUM(AD27:AK27) -> 50 | AM27: =ROUND(AL27/70*10,2) -> 7.14 | AN27: =ROUND(S27*0.2+AC27*0.4+AM27*0.4,2) -> 6.71 | AO27: CHF | AP27: 415 | AQ27: 475 | AR27: =I27-AP27+AQ27 -> 14882.955 | AS27: 261.6 | AT27: 528 | AU27: 779 | AV27: 2637 | AW27: =AR27/AS27 -> 56.892031 | AX27: =AR27/AU27 -> 19.105206 | AY27: =AR27/AV27 -> 5.6438966 | AZ27: 3139 | BA27: =AT27/AV27 -> 0.20022753 | BB27: =AV27/AZ27 -> 0.84007646 | BC27: =BA27*BB27 -> 0.16820644 | BD27: 350.2 | BE27: =(BD27/AS27)^(1/5)-1 -> 0.060072774 | BF27: 549.8 | BG27: =(BF27/AS27)^(1/5)-1 -> 0.16014801 | BH27: 18 | BI27: 25 | BJ27: =(BD27*BH27+$AP27-$AQ27)/$H27 -> 39.155826 | BK27: =(BF27*BI27+$AP27-$AQ27)/$H27 -> 85.823479 | BL27: =IF($BJ27<=0,-0.99,MAX(-0.99,($BJ27/G27)^(1/5)-1)) -> -0.15879847 | BM27: =IF(BK27<=0,-0.99,MAX(-0.99,(BK27/G27)^(1/5)-1)) -> -0.015848406 | BN27: 2026-08-25 | BO27: 19/08/2026 | BP27: 29/10/2026 | BQ27: 18.9 | BR27: 65.4 | BS27: 327 | BT27: anual
A28: #VALUE! | B28: {=_FV(A28,"Símbolo bursátil",TRUE())} -> META | C28: Mag 7 | D28: Compounder | E28: {=_FV(A28,"Abreviatura de intercambio",TRUE())} -> XNAS | F28: {=_FV(A28,"Moneda")} -> USD | G28: {=_FV(A28,"Precio")} -> 704.29 | H28: {=_FV(A28,"Acciones en circulación",TRUE())/1000000} -> 2547.506 | I28: =G28*H28 -> 1794183 | J28: -0.5 | K28: 7 | L28: 2 | M28: 1 | N28: -1 | O28: 0 | P28: 1 | Q28: 1 | R28: =SUM(J28:N28)+SUM(P28:Q28) -> 10.5 | S28: =ROUND(R28/16*10,2) -> 6.56 | T28: 15 | U28: 18 | V28: 12 | W28: 8 | X28: 8 | Y28: 10 | Z28: 9 | AA28: -15 | AB28: =SUM(T28:AA28) -> 65 | AC28: =ROUND(AB28/10,2) -> 6.5 | AD28: 12 | AE28: -3 | AF28: 5 | AG28: 12 | AH28: 3 | AI28: 8 | AJ28: 13 | AK28: -6 | AL28: =SUM(AD28:AK28) -> 44 | AM28: =ROUND(AL28/70*10,2) -> 6.29 | AN28: =ROUND(S28*0.2+AC28*0.4+AM28*0.4,2) -> 6.43 | AO28: USD | AP28: 90260 | AQ28: 112320 | AR28: =I28-AP28+AQ28 -> 1816243 | AS28: 15840 | AT28: 67631 | AU28: 109660 | AV28: 228250 | AW28: =AR28/AS28 -> 114.66181 | AX28: =AR28/AU28 -> 16.562493 | AY28: =AR28/AV28 -> 7.957253 | AZ28: 393577 | BA28: =AT28/AV28 -> 0.2963023 | BB28: =AV28/AZ28 -> 0.57993734 | BC28: =BA28*BB28 -> 0.17183677 | BD28: 62609.7 | BE28: =(BD28/BS28)^(1/5)-1 -> -0.053534163 | BF28: 173143.7 | BG28: =(BF28/BS28)^(1/5)-1 -> 0.15999991 | BH28: 18 | BI28: 26 | BJ28: =(BD28*BH28+$AP28-$AQ28)/$H28 -> 433.72404 | BK28: =(BF28*BI28+$AP28-$AQ28)/$H28 -> 1758.4556 | BL28: =IF($BJ28<=0,-0.99,MAX(-0.99,($BJ28/G28)^(1/5)-1)) -> -0.092404372 | BM28: =IF(BK28<=0,-0.99,MAX(-0.99,(BK28/G28)^(1/5)-1)) -> 0.20081465 | BN28: 2026-08-26 | BO28: 29/07/2026 | BP28: 28/10/2026 | BQ28: 25136 | BR28: 66596 | BS28: 82436 | BT28: FCF@5y NORMALIZADO el 4-oct-2026 por decision de Roger: BD/BF del 8-sep x BS/AS (82.436/15.840 = 5,204). BD 12.030,4 -> 62.609,7; BF 33.269,4 -> 173.143,7. CAGR sobre el normalizado -5,4% / 16,0% (las de Roger). BE/BG pasan a medirse contra BS. Multiplos sin cambio por decision de Roger: se calibraron el 22-ago sobre FCF@5y normalizado.
A29: #VALUE! | B29: {=_FV(A29,"Símbolo bursátil",TRUE())} -> KKR | C29: Real Assets | D29: Compounder | E29: {=_FV(A29,"Abreviatura de intercambio",TRUE())} -> XNYS | F29: {=_FV(A29,"Moneda")} -> USD | G29: {=_FV(A29,"Precio")} -> 86.855 | H29: {=_FV(A29,"Acciones en circulación",TRUE())/1000000} -> 897.6356 | I29: =G29*H29 -> 77964.14 | J29: 0 | K29: 6 | L29: 2 | M29: 0 | N29: 0 | O29: 0 | P29: 1 | Q29: 1 | R29: =SUM(J29:N29)+SUM(P29:Q29) -> 10 | S29: =ROUND(R29/16*10,2) -> 6.25 | T29: 13 | U29: 15 | V29: 14 | W29: 9 | X29: 9 | Y29: 13 | Z29: 9 | AA29: -10 | AB29: =SUM(T29:AA29) -> 72 | AC29: =ROUND(AB29/10,2) -> 7.2 | AD29: 13 | AE29: -3 | AF29: 7 | AG29: 13 | AH29: 2 | AI29: 9 | AJ29: 12 | AK29: -5 | AL29: =SUM(AD29:AK29) -> 48 | AM29: =ROUND(AL29/70*10,2) -> 6.86 | AN29: =ROUND(S29*0.2+AC29*0.4+AM29*0.4,2) -> 6.87 | AO29: USD | AP29: 21080 | AQ29: 56164 | AR29: =I29-AP29+AQ29 -> 113048.14 | AS29: 5000 | AT29: 5176 | AU29: 6752 | AV29: 25833 | AW29: =AR29/AS29 -> 22.609628 | AX29: =AR29/AU29 -> 16.742912 | AY29: =AR29/AV29 -> 4.3761135 | AZ29: 34500 | BA29: =AT29/AV29 -> 0.20036388 | BB29: =AV29/AZ29 -> 0.74878261 | BC29: =BA29*BB29 -> 0.15002899 | BD29: 7013 | BE29: =(BD29/AS29)^(1/5)-1 -> 0.070007365 | BF29: 12442 | BG29: =(BF29/AS29)^(1/5)-1 -> 0.20000772 | BH29: 15 | BI29: 25 | BJ29: =(BD29*BH29+$AP29-$AQ29)/$H29 -> 78.106305 | BK29: =(BF29*BI29+$AP29-$AQ29)/$H29 -> 307.43656 | BL29: =IF($BJ29<=0,-0.99,MAX(-0.99,($BJ29/G29)^(1/5)-1)) -> -0.021010004 | BM29: =IF(BK29<=0,-0.99,MAX(-0.99,(BK29/G29)^(1/5)-1)) -> 0.28763311 | BN29: 2026-08-26 | BO29: 30/07/2026 | BP29: 04/11/2026
A30: #VALUE! | B30: {=_FV(A30,"Símbolo bursátil",TRUE())} -> NET | C30: Cyber | D30: Growth | E30: {=_FV(A30,"Abreviatura de intercambio",TRUE())} -> XNYS | F30: {=_FV(A30,"Moneda")} -> USD | G30: {=_FV(A30,"Precio")} -> 299.195 | H30: {=_FV(A30,"Acciones en circulación",TRUE())/1000000} -> 356.0797 | I30: =G30*H30 -> 106537.27 | J30: 1 | K30: 5 | L30: 3 | M30: 0 | N30: 0 | O30: 1 | P30: 1 | Q30: 0 | R30: =SUM(J30:N30)+SUM(P30:Q30) -> 10 | S30: =ROUND(R30/16*10,2) -> 6.25 | T30: 7 | U30: 13 | V30: 16 | W30: 9 | X30: 7 | Y30: 12 | Z30: 6 | AA30: -12 | AB30: =SUM(T30:AA30) -> 58 | AC30: =ROUND(AB30/10,2) -> 5.8 | AD30: 13 | AE30: -1 | AF30: 6 | AG30: 10 | AH30: 3 | AI30: 8 | AJ30: 11 | AK30: -4 | AL30: =SUM(AD30:AK30) -> 46 | AM30: =ROUND(AL30/70*10,2) -> 6.57 | AN30: =ROUND(S30*0.2+AC30*0.4+AM30*0.4,2) -> 6.2 | AO30: USD | AP30: 4163 | AQ30: 3529 | AR30: =I30-AP30+AQ30 -> 105903.27 | AS30: -192.8 | AT30: -195 | AU30: -2 | AV30: 2512 | AW30: =AR30/AS30 -> -549.2908 | AX30: =AR30/AU30 -> -52951.633 | AY30: =AR30/AV30 -> 42.158943 | AZ30: 3846 | BA30: =AT30/AV30 -> -0.077627389 | BB30: =AV30/AZ30 -> 0.65314613 | BC30: =BA30*BB30 -> -0.050702028 | BD30: -109 | BE30: =(BD30/AS30)^(1/5)-1 -> -0.10779656 | BF30: 408 | BG30: =(BF30/AS30)^(1/5)-1 -> -2.1617445 | BH30: 20 | BI30: 30 | BJ30: =(BD30*BH30+$AP30-$AQ30)/$H30 -> -4.3417246 | BK30: =(BF30*BI30+$AP30-$AQ30)/$H30 -> 36.154827 | BL30: =IF($BJ30<=0,-0.99,MAX(-0.99,($BJ30/G30)^(1/5)-1)) -> -0.99 | BM30: =IF(BK30<=0,-0.99,MAX(-0.99,(BK30/G30)^(1/5)-1)) -> -0.34469664 | BN30: 2026-08-25 | BO30: 06/08/2026 | BP30: 05/11/2026 | BQ30: 507.7 | BR30: 93.4 | BS30: -99.4 | BT30: FCF-SBC NEGATIVO: SBC = 20% ingresos. FCF@5y pasado a post-SBC: ingresos y5 7.666 (25%/a) x SBC 10% = -767 sobre 658/1.175. EV/FCF no computable a este precio
A31: #VALUE! | B31: {=_FV(A31,"Símbolo bursátil",TRUE())} -> CRWD | C31: Cyber | D31: Growth | E31: {=_FV(A31,"Abreviatura de intercambio",TRUE())} -> XNAS | F31: {=_FV(A31,"Moneda")} -> USD | G31: {=_FV(A31,"Precio")} -> 228.59 | H31: {=_FV(A31,"Acciones en circulación",TRUE())/1000000} -> 1023.935 | I31: =G31*H31 -> 234061.3 | J31: 1 | K31: 6 | L31: 2 | M31: 0 | N31: 0 | O31: 0 | P31: 1 | Q31: 0 | R31: =SUM(J31:N31)+SUM(P31:Q31) -> 10 | S31: =ROUND(R31/16*10,2) -> 6.25 | T31: 12 | U31: 16 | V31: 16 | W31: 8 | X31: 9 | Y31: 10 | Z31: 5 | AA31: -10 | AB31: =SUM(T31:AA31) -> 66 | AC31: =ROUND(AB31/10,2) -> 6.6 | AD31: 12 | AE31: -2 | AF31: 9 | AG31: 11 | AH31: 3 | AI31: 7 | AJ31: 12 | AK31: -5 | AL31: =SUM(AD31:AK31) -> 47 | AM31: =ROUND(AL31/70*10,2) -> 6.71 | AN31: =ROUND(S31*0.2+AC31*0.4+AM31*0.4,2) -> 6.57 | AO31: USD | AP31: 5013.8 | AQ31: 746.2 | AR31: =I31-AP31+AQ31 -> 229793.7 | AS31: 281.6 | AT31: -133 | AV31: 5396.1 | AW31: =AR31/AS31 -> 816.02877 | AX31: =AR31/AU31 -> #VALUE! | AY31: =AR31/AV31 -> 42.585145 | AZ31: 7154 | BA31: =AT31/AV31 -> -0.024647431 | BB31: =AV31/AZ31 -> 0.75427733 | BC31: =BA31*BB31 -> -0.018590998 | BD31: 491 | BE31: =(BD31/AS31)^(1/5)-1 -> 0.11760869 | BF31: 884.8 | BG31: =(BF31/AS31)^(1/5)-1 -> 0.25731036 | BH31: 20 | BI31: 30 | BJ31: =(BD31*BH31+$AP31-$AQ31)/$H31 -> 13.758295 | BK31: =(BF31*BI31+$AP31-$AQ31)/$H31 -> 30.091363 | BL31: =IF($BJ31<=0,-0.99,MAX(-0.99,($BJ31/G31)^(1/5)-1)) -> -0.42996506 | BM31: =IF(BK31<=0,-0.99,MAX(-0.99,(BK31/G31)^(1/5)-1)) -> -0.33338217 | BN31: 2026-09-27 | BO31: 26/08/2026 | BP31: 01/12/2026 | BQ31: 1244 | BR31: 0 | BS31: 281.6 | BT31: FUENTE: 10-Q Q2 FY27 (EDGAR XBRL). OCF 2.016,6 - capex 407,9 - software 83,1 - SBC 1.244 = 281,6. D&A no etiquetada de forma completa: sin normalizar y EBITDA pendiente. Deuda 746,2. Proximos estimados
A32: #VALUE! | B32: {=_FV(A32,"Símbolo bursátil",TRUE())} -> GOOG | C32: Mag 7 | D32: Compounder | E32: {=_FV(A32,"Abreviatura de intercambio",TRUE())} -> XNAS | F32: {=_FV(A32,"Moneda")} -> USD | G32: {=_FV(A32,"Precio")} -> 340.38 | H32: {=_FV(A32,"Acciones en circulación",TRUE())/1000000} -> 12230 | I32: =G32*H32 -> 4162847.4 | J32: 1 | K32: 7 | L32: 3 | M32: 1 | N32: -1 | O32: 1 | P32: 1 | Q32: 0 | R32: =SUM(J32:N32)+SUM(P32:Q32) -> 12 | S32: =ROUND(R32/16*10,2) -> 7.5 | T32: 16 | U32: 18 | V32: 13 | W32: 8 | X32: 8 | Y32: 11 | Z32: 6 | AA32: -14 | AB32: =SUM(T32:AA32) -> 66 | AC32: =ROUND(AB32/10,2) -> 6.6 | AD32: 12 | AE32: -4 | AF32: 5 | AG32: 11 | AH32: 4 | AI32: 7 | AJ32: 13 | AK32: -6 | AL32: =SUM(AD32:AK32) -> 42 | AM32: =ROUND(AL32/70*10,2) -> 6 | AN32: =ROUND(S32*0.2+AC32*0.4+AM32*0.4,2) -> 6.54 | AO32: USD | AP32: 242470 | AQ32: 120790 | AR32: =I32-AP32+AQ32 -> 4041167.4 | AS32: 25126 | AT32: 120466 | AU32: 173160 | AV32: 445870 | AW32: =AR32/AS32 -> 160.83608 | AX32: =AR32/AU32 -> 23.337765 | AY32: =AR32/AV32 -> 9.0635553 | AZ32: 795872 | BA32: =AT32/AV32 -> 0.27018189 | BB32: =AV32/AZ32 -> 0.56022828 | BC32: =BA32*BB32 -> 0.15136354 | BD32: 168840.3 | BE32: =(BD32/BS32)^(1/5)-1 -> 0.049999671 | BF32: 266084.7 | BG32: =(BF32/BS32)^(1/5)-1 -> 0.15000021 | BH32: 20 | BI32: 30 | BJ32: =(BD32*BH32+$AP32-$AQ32)/$H32 -> 286.05773 | BK32: =(BF32*BI32+$AP32-$AQ32)/$H32 -> 662.65094 | BL32: =IF($BJ32<=0,-0.99,MAX(-0.99,($BJ32/G32)^(1/5)-1)) -> -0.034176141 | BM32: =IF(BK32<=0,-0.99,MAX(-0.99,(BK32/G32)^(1/5)-1)) -> 0.14252091 | BN32: 2026-08-25 | BO32: 22/07/2026 | BP32: 27/10/2026 | BQ32: 28147 | BR32: 107165 | BS32: 132291 | BT32: FCF@5y NORMALIZADO el 4-oct-2026 por decision de Roger: BD/BF del 8-sep x BS/AS (132.291/25.126 = 5,265). BD 32.067,8 -> 168.840,3; BF 50.537,4 -> 266.084,7. CAGR sobre el normalizado 5,0% / 15,0% (las de Roger). BE/BG pasan a medirse contra BS. Multiplos sin cambio por decision de Roger: se calibraron el 22-ago sobre FCF@5y normalizado.
A33: #VALUE! | B33: {=_FV(A33,"Símbolo bursátil",TRUE())} -> ABBNE | C33: Electrify | D33: Compounder | E33: {=_FV(A33,"Abreviatura de intercambio",TRUE())} -> XSWX | F33: {=_FV(A33,"Moneda")} -> CHF | G33: {=_FV(A33,"Precio")} -> 74.62 | H33: {=_FV(A33,"Acciones en circulación",TRUE())/1000000} -> 1823.154 | I33: =G33*H33 -> 136043.75 | J33: 1 | K33: 6 | L33: 2 | M33: 1 | N33: 0 | O33: 0 | P33: 0 | Q33: 0 | R33: =SUM(J33:N33)+SUM(P33:Q33) -> 10 | S33: =ROUND(R33/16*10,2) -> 6.25 | T33: 13 | U33: 14 | V33: 13 | W33: 9 | X33: 8 | Y33: 11 | Z33: 4 | AA33: -8 | AB33: =SUM(T33:AA33) -> 64 | AC33: =ROUND(AB33/10,2) -> 6.4 | AD33: 12 | AE33: -2 | AF33: 5 | AG33: 12 | AH33: 4 | AI33: 7 | AJ33: 11 | AK33: -4 | AL33: =SUM(AD33:AK33) -> 45 | AM33: =ROUND(AL33/70*10,2) -> 6.43 | AN33: =ROUND(S33*0.2+AC33*0.4+AM33*0.4,2) -> 6.38 | AO33: USD | AP33: 5860 | AQ33: 9150 | AR33: =I33*'Framework Notes'!E5-AP33+AQ33 -> 167875.73 | AS33: 4159 | AT33: 4811 | AU33: 7150 | AV33: 35750 | AW33: =AR33/AS33 -> 40.364446 | AX33: =AR33/AU33 -> 23.479123 | AY33: =AR33/AV33 -> 4.6958246 | AZ33: 27296 | BA33: =AT33/AV33 -> 0.13457343 | BB33: =AV33/AZ33 -> 1.3097157 | BC33: =BA33*BB33 -> 0.17625293 | BD33: 5060.1 | BE33: =(BD33/AS33)^(1/5)-1 -> 0.040001668 | BF33: 7329.7 | BG33: =(BF33/AS33)^(1/5)-1 -> 0.1200037 | BH33: 14 | BI33: 25 | BJ33: =((BD33*BH33+$AP33-$AQ33)/$H33)/'Framework Notes'!E5 -> 30.626504 | BK33: =((BF33*BI33+$AP33-$AQ33)/$H33)/'Framework Notes'!E5 -> 81.586997 | BL33: =IF($BJ33<=0,-0.99,MAX(-0.99,($BJ33/G33)^(1/5)-1)) -> -0.16314843 | BM33: =IF(BK33<=0,-0.99,MAX(-0.99,(BK33/G33)^(1/5)-1)) -> 0.018012571 | BN33: 2026-08-25 | BO33: 16/07/2026 | BP33: 22/10/2026 | BQ33: 0 | BR33: 175 | BS33: 4334 | BT33: no reportado (0)
A34: #VALUE! | B34: {=_FV(A34,"Símbolo bursátil",TRUE())} -> GRMN | C34: Sports | D34: Compounder | E34: {=_FV(A34,"Abreviatura de intercambio",TRUE())} -> XNYS | F34: {=_FV(A34,"Moneda")} -> USD | G34: {=_FV(A34,"Precio")} -> 285.15 | H34: {=_FV(A34,"Acciones en circulación",TRUE())/1000000} -> 192.8525 | I34: =G34*H34 -> 54991.89 | J34: 0 | K34: 5 | L34: 2 | M34: 1 | N34: 0 | O34: 1 | P34: 0 | Q34: 0 | R34: =SUM(J34:N34)+SUM(P34:Q34) -> 8 | S34: =ROUND(R34/16*10,2) -> 5 | T34: 14 | U34: 13 | V34: 10 | W34: 8 | X34: 8 | Y34: 10 | Z34: 6 | AA34: -7 | AB34: =SUM(T34:AA34) -> 62 | AC34: =ROUND(AB34/10,2) -> 6.2 | AD34: 12 | AE34: -2 | AF34: 8 | AG34: 10 | AH34: 5 | AI34: 7 | AJ34: 10 | AK34: -3 | AL34: =SUM(AD34:AK34) -> 47 | AM34: =ROUND(AL34/70*10,2) -> 6.71 | AN34: =ROUND(S34*0.2+AC34*0.4+AM34*0.4,2) -> 6.16 | AO34: USD | AP34: 2670 | AQ34: 227 | AR34: =I34-AP34+AQ34 -> 52548.89 | AS34: 1427.3 | AT34: 1754 | AU34: 2310 | AV34: 7670 | AW34: =AR34/AS34 -> 36.81699 | AX34: =AR34/AU34 -> 22.748437 | AY34: =AR34/AV34 -> 6.8512243 | AZ34: 9341 | BA34: =AT34/AV34 -> 0.22868318 | BB34: =AV34/AZ34 -> 0.82111123 | BC34: =BA34*BB34 -> 0.18777433 | BD34: 1736.9 | BE34: =(BD34/AS34)^(1/5)-1 -> 0.040044472 | BF34: 2629.5 | BG34: =(BF34/AS34)^(1/5)-1 -> 0.12998215 | BH34: 18 | BI34: 26 | BJ34: =(BD34*BH34+$AP34-$AQ34)/$H34 -> 174.78228 | BK34: =(BF34*BI34+$AP34-$AQ34)/$H34 -> 367.1718 | BL34: =IF($BJ34<=0,-0.99,MAX(-0.99,($BJ34/G34)^(1/5)-1)) -> -0.093255759 | BM34: =IF(BK34<=0,-0.99,MAX(-0.99,(BK34/G34)^(1/5)-1)) -> 0.051863025 | BN34: 2026-08-25 | BO34: 29/07/2026 | BP34: 29/10/2026 | BQ34: 172.5 | BR34: 185.8 | BS34: 1613.1 | BT34: trimestral
